Workbook
Name Instrumentalist: 'Lookup tables'!$K$1:$N$5

Sheet Recent Bhajans
A1: =IFERROR(__xludf.DUMMYFUNCTION("QUERY('Singer Roster'!D2:D1000, ""select D, count(D) where D is not null group by D label D 'Bhajan', count(D) 'Count'"")"),"Bhajan") -> Bhajan | B1: =IFERROR(__xludf.DUMMYFUNCTION("""COMPUTED_VALUE"""),"Count") -> Count | C1: {={"Deity"; IF(A2:A1000="", "", IFERROR(VLOOKUP(A2:A1000, 'Bhajan Masterlist'!B:G, 6, FALSE), ""))}} -> Deity
A2: =IFERROR(__xludf.DUMMYFUNCTION("""COMPUTED_VALUE"""),"Aao Aao Nandalala") -> Aao Aao Nandalala | B2: =IFERROR(__xludf.DUMMYFUNCTION("""COMPUTED_VALUE"""),1.0) -> 1 | C2: Krishna
A3: =IFERROR(__xludf.DUMMYFUNCTION("""COMPUTED_VALUE"""),"Aao Aao Sai Pyaarey") -> Aao Aao Sai Pyaarey | B3: =IFERROR(__xludf.DUMMYFUNCTION("""COMPUTED_VALUE"""),2.0) -> 2 | C3: Sai
A4: =IFERROR(__xludf.DUMMYFUNCTION("""COMPUTED_VALUE"""),"Aao Gopala Giridhari") -> Aao Gopala Giridhari | B4: =IFERROR(__xludf.DUMMYFUNCTION("""COMPUTED_VALUE"""),1.0) -> 1 | C4: Krishna
A5: =IFERROR(__xludf.DUMMYFUNCTION("""COMPUTED_VALUE"""),"Aao Pyaarey Nayana Hamarey") -> Aao Pyaarey Nayana Hamarey | B5: =IFERROR(__xludf.DUMMYFUNCTION("""COMPUTED_VALUE"""),1.0) -> 1 | C5: Sai
A6: =IFERROR(__xludf.DUMMYFUNCTION("""COMPUTED_VALUE"""),"Abhayankara Sai Shiva") -> Abhayankara Sai Shiva | B6: =IFERROR(__xludf.DUMMYFUNCTION("""COMPUTED_VALUE"""),1.0) -> 1 | C6: Shiva
A7: =IFERROR(__xludf.DUMMYFUNCTION("""COMPUTED_VALUE"""),"Adi Poojya Deva Gajanana") -> Adi Poojya Deva Gajanana | B7: =IFERROR(__xludf.DUMMYFUNCTION("""COMPUTED_VALUE"""),1.0) -> 1 | C7: Ganesha
A8: =IFERROR(__xludf.DUMMYFUNCTION("""COMPUTED_VALUE"""),"Akhila Jagat Ke Daata Sai") -> Akhila Jagat Ke Daata Sai | B8: =IFERROR(__xludf.DUMMYFUNCTION("""COMPUTED_VALUE"""),2.0) -> 2 | C8: Sai
A9: =IFERROR(__xludf.DUMMYFUNCTION("""COMPUTED_VALUE"""),"Amba Bhavani Shiva Shambhu Kumara") -> Amba Bhavani Shiva Shambhu Kumara | B9: =IFERROR(__xludf.DUMMYFUNCTION("""COMPUTED_VALUE"""),1.0) -> 1 | C9: Ganesha
A10: =IFERROR(__xludf.DUMMYFUNCTION("""COMPUTED_VALUE"""),"Amba Shankari Parameshwari Shashi Shekari") -> Amba Shankari Parameshwari Shashi Shekari | B10: =IFERROR(__xludf.DUMMYFUNCTION("""COMPUTED_VALUE"""),3.0) -> 3 | C10: Devi
A11: =IFERROR(__xludf.DUMMYFUNCTION("""COMPUTED_VALUE"""),"Ambika Tanaya Gajanana") -> Ambika Tanaya Gajanana | B11: =IFERROR(__xludf.DUMMYFUNCTION("""COMPUTED_VALUE"""),6.0) -> 6 | C11: Ganesha
A12: =IFERROR(__xludf.DUMMYFUNCTION("""COMPUTED_VALUE"""),"Ananda Ram Ananda Shyam") -> Ananda Ram Ananda Shyam | B12: =IFERROR(__xludf.DUMMYFUNCTION("""COMPUTED_VALUE"""),2.0) -> 2 | C12: Narayana
A13: =IFERROR(__xludf.DUMMYFUNCTION("""COMPUTED_VALUE"""),"Anandamaya Bhagawan") -> Anandamaya Bhagawan | B13: =IFERROR(__xludf.DUMMYFUNCTION("""COMPUTED_VALUE"""),1.0) -> 1 | C13: Sai
A14: =IFERROR(__xludf.DUMMYFUNCTION("""COMPUTED_VALUE"""),"Anandamey Sai Naamamey") -> Anandamey Sai Naamamey | B14: =IFERROR(__xludf.DUMMYFUNCTION("""COMPUTED_VALUE"""),1.0) -> 1 | C14: Sai
A15: =IFERROR(__xludf.DUMMYFUNCTION("""COMPUTED_VALUE"""),"Anantha Premamrutha Sai") -> Anantha Premamrutha Sai | B15: =IFERROR(__xludf.DUMMYFUNCTION("""COMPUTED_VALUE"""),1.0) -> 1 | C15: Sai
A16: =IFERROR(__xludf.DUMMYFUNCTION("""COMPUTED_VALUE"""),"Anatha Bandho Sai Prabho") -> Anatha Bandho Sai Prabho | B16: =IFERROR(__xludf.DUMMYFUNCTION("""COMPUTED_VALUE"""),1.0) -> 1 | C16: Sai
A17: =IFERROR(__xludf.DUMMYFUNCTION("""COMPUTED_VALUE"""),"Antar Jyothi Jalao Sai") -> Antar Jyothi Jalao Sai | B17: =IFERROR(__xludf.DUMMYFUNCTION("""COMPUTED_VALUE"""),1.0) -> 1 | C17: Sai
A18: =IFERROR(__xludf.DUMMYFUNCTION("""COMPUTED_VALUE"""),"Antaranga Sai Anatha Natha Sai") -> Antaranga Sai Anatha Natha Sai | B18: =IFERROR(__xludf.DUMMYFUNCTION("""COMPUTED_VALUE"""),1.0) -> 1 | C18: Sai
A19: =IFERROR(__xludf.DUMMYFUNCTION("""COMPUTED_VALUE"""),"Antaryami Sai") -> Antaryami Sai | B19: =IFERROR(__xludf.DUMMYFUNCTION("""COMPUTED_VALUE"""),2.0) -> 2 | C19: Sai
A20: =IFERROR(__xludf.DUMMYFUNCTION("""COMPUTED_VALUE"""),"Araj Suno Merey Parama Krupalu") -> Araj Suno Merey Parama Krupalu | B20: =IFERROR(__xludf.DUMMYFUNCTION("""COMPUTED_VALUE"""),1.0) -> 1 | C20: Sai
A21: =IFERROR(__xludf.DUMMYFUNCTION("""COMPUTED_VALUE"""),"Aruna Ramana Sri Guru Deva") -> Aruna Ramana Sri Guru Deva | B21: =IFERROR(__xludf.DUMMYFUNCTION("""COMPUTED_VALUE"""),1.0) -> 1 | C21: Guru
A22: =IFERROR(__xludf.DUMMYFUNCTION("""COMPUTED_VALUE"""),"Arunachala Shiva, Arunachala Shiva") -> Arunachala Shiva, Arunachala Shiva | B22: =IFERROR(__xludf.DUMMYFUNCTION("""COMPUTED_VALUE"""),1.0) -> 1 | C22: Shiva
A23: =IFERROR(__xludf.DUMMYFUNCTION("""COMPUTED_VALUE"""),"Atma Lingam Bhajorey") -> Atma Lingam Bhajorey | B23: =IFERROR(__xludf.DUMMYFUNCTION("""COMPUTED_VALUE"""),2.0) -> 2 | C23: Shiva
A24: =IFERROR(__xludf.DUMMYFUNCTION("""COMPUTED_VALUE"""),"Atma Ram Ananda Dham") -> Atma Ram Ananda Dham | B24: =IFERROR(__xludf.DUMMYFUNCTION("""COMPUTED_VALUE"""),1.0) -> 1 | C24: Rama
A25: =IFERROR(__xludf.DUMMYFUNCTION("""COMPUTED_VALUE"""),"Ayodhya Shiromani Dasharatha Rama") -> Ayodhya Shiromani Dasharatha Rama | B25: =IFERROR(__xludf.DUMMYFUNCTION("""COMPUTED_VALUE"""),2.0) -> 2 | C25: Rama
A26: =IFERROR(__xludf.DUMMYFUNCTION("""COMPUTED_VALUE"""),"Ayodhya Vasi Ram Ram Ram") -> Ayodhya Vasi Ram Ram Ram | B26: =IFERROR(__xludf.DUMMYFUNCTION("""COMPUTED_VALUE"""),1.0) -> 1 | C26: Rama
A27: =IFERROR(__xludf.DUMMYFUNCTION("""COMPUTED_VALUE"""),"Ayodhya Vihari Sri Rama Rama") -> Ayodhya Vihari Sri Rama Rama | B27: =IFERROR(__xludf.DUMMYFUNCTION("""COMPUTED_VALUE"""),2.0) -> 2 | C27: Rama, Krishna
A28: =IFERROR(__xludf.DUMMYFUNCTION("""COMPUTED_VALUE"""),"Baar Baar Tum Aao Sai") -> Baar Baar Tum Aao Sai | B28: =IFERROR(__xludf.DUMMYFUNCTION("""COMPUTED_VALUE"""),3.0) -> 3 | C28: Sai
A29: =IFERROR(__xludf.DUMMYFUNCTION("""COMPUTED_VALUE"""),"Baba Aao Merey Keertan Mey") -> Baba Aao Merey Keertan Mey | B29: =IFERROR(__xludf.DUMMYFUNCTION("""COMPUTED_VALUE"""),1.0) -> 1 | C29: Sai
A30: =IFERROR(__xludf.DUMMYFUNCTION("""COMPUTED_VALUE"""),"Bala Gopal Jai Jai Sai Shyam") -> Bala Gopal Jai Jai Sai Shyam | B30: =IFERROR(__xludf.DUMMYFUNCTION("""COMPUTED_VALUE"""),1.0) -> 1 | C30: Sai
A31: =IFERROR(__xludf.DUMMYFUNCTION("""COMPUTED_VALUE"""),"Bala Gopala Sai") -> Bala Gopala Sai | B31: =IFERROR(__xludf.DUMMYFUNCTION("""COMPUTED_VALUE"""),1.0) -> 1 | C31: Krishna
A32: =IFERROR(__xludf.DUMMYFUNCTION("""COMPUTED_VALUE"""),"Bansi Bajao Man Mandir Mey") -> Bansi Bajao Man Mandir Mey | B32: =IFERROR(__xludf.DUMMYFUNCTION("""COMPUTED_VALUE"""),2.0) -> 2 | C32: Krishna
A33: =IFERROR(__xludf.DUMMYFUNCTION("""COMPUTED_VALUE"""),"Bansidhara Kanhaiya") -> Bansidhara Kanhaiya | B33: =IFERROR(__xludf.DUMMYFUNCTION("""COMPUTED_VALUE"""),1.0) -> 1 | C33: Krishna
A34: =IFERROR(__xludf.DUMMYFUNCTION("""COMPUTED_VALUE"""),"Bhairavi Ambe Bhavani") -> Bhairavi Ambe Bhavani | B34: =IFERROR(__xludf.DUMMYFUNCTION("""COMPUTED_VALUE"""),1.0) -> 1 | C34: Devi
A35: =IFERROR(__xludf.DUMMYFUNCTION("""COMPUTED_VALUE"""),"Bhaja Mana Govinda Gopala") -> Bhaja Mana Govinda Gopala | B35: =IFERROR(__xludf.DUMMYFUNCTION("""COMPUTED_VALUE"""),2.0) -> 2 | C35: Krishna
A36: =IFERROR(__xludf.DUMMYFUNCTION("""COMPUTED_VALUE"""),"Bhaja Mana Shyama Sundara Giridhari (Pilu)") -> Bhaja Mana Shyama Sundara Giridhari (Pilu) | B36: =IFERROR(__xludf.DUMMYFUNCTION("""COMPUTED_VALUE"""),1.0) -> 1 | C36: Krishna
A37: =IFERROR(__xludf.DUMMYFUNCTION("""COMPUTED_VALUE"""),"Bhaja Ranga Harey Vittala") -> Bhaja Ranga Harey Vittala | B37: =IFERROR(__xludf.DUMMYFUNCTION("""COMPUTED_VALUE"""),2.0) -> 2 | C37: Vittala
A38: =IFERROR(__xludf.DUMMYFUNCTION("""COMPUTED_VALUE"""),"Bhajan Karo Manuva Govinda Harey") -> Bhajan Karo Manuva Govinda Harey | B38: =IFERROR(__xludf.DUMMYFUNCTION("""COMPUTED_VALUE"""),2.0) -> 2 | C38: Krishna
A39: =IFERROR(__xludf.DUMMYFUNCTION("""COMPUTED_VALUE"""),"Bhajarey Rama Charan Satatam Bhajarey") -> Bhajarey Rama Charan Satatam Bhajarey | B39: =IFERROR(__xludf.DUMMYFUNCTION("""COMPUTED_VALUE"""),3.0) -> 3 | C39: Rama
A40: =IFERROR(__xludf.DUMMYFUNCTION("""COMPUTED_VALUE"""),"Bhajo Bhajo Vittala Panduranga Vittala") -> Bhajo Bhajo Vittala Panduranga Vittala | B40: =IFERROR(__xludf.DUMMYFUNCTION("""COMPUTED_VALUE"""),2.0) -> 2 | C40: Vittala
...

Sheet Singer Roster
B1: Singer | C1: Festival Singer | D1: Bhajan | E1: Festival Bhajan | F1: Input only IF Bhajan (NOT in database) | G1: Confirmed Pitch | H1: Alternative Tabla Pitch | I1: Recommended Pitch as Sai Rythms | J1: Raga | K1: Lyrics | L1: Meaning
A3: 45734 | B3: Prithvi | D3: Gananatha Sai Gajanana | G3: 1 Pancham / C | H3: {=IFNA(INDEX(Pitches[],MATCH($G3,Pitches[Pitches],0),2),"")} -> G | I3: {=IF( AND(D3="", E3=""), "", IFNA( IF( INDEX(Singers[], MATCH(IF(D3<>"", B3, C3), Singers[Singers], 0), 2, 0) = "Gents", INDEX(Bhajans[], MATCH(IF(D3<>"", D3, E3), Bhajans[title], 0), 13), INDEX(Bhajans[], MATCH(IF(D3<>"", D3, E3), Bhajans[title], 0), 14) ), "" ) )} -> 1 Pancham / C | J3: {=IF(AND($D3="", $E3=""), "", IFNA(INDEX(Bhajans[], MATCH(IF($D3<>"", $D3, $E3), Bhajans[title], 0), 9), ""))} -> Darbari | K3: {=IF(AND($D3="", $E3=""), "", IFNA(INDEX(Bhajans[], MATCH(IF($D3<>"", $D3, $E3), Bhajans[title], 0), 5), ""))} -> Gananatha Sai Gajanana Partheeshwara Dukha Bhanjana [ Gananatha ... ] Kailasa Pathey Shiva Nandana Deena Natha Harey Hey Niranjana Siddhi Pradatha Shubhanana Jagadeeshwara Shanthi Niketana Jagadeeshwara Shanthi Niketana | L3: {=IF(AND($D3="", $E3=""), "", IFNA(INDEX(Bhajans[], MATCH(IF($D3<>"", $D3, $E3), Bhajans[title], 0), 4), ""))} -> O Lord Ganesha, the Lord of all Ganaas (Demigods), O Lord of Parthi, You relieve us of all anxieties and sadness. O the Son of Shiva (the Lord of Kailasa), who is the embodiment of purity and the Lord of the destitute, O bestower of all the siddhis and prowess, the one whose face radiates goodness, O sustainer of the whole world and the abode of all peace, glory be to Thee.
A4: 45734 | B4: Sailavan | C4: {=IFNA(XLOOKUP(E4,GP_Bhajan_List[GP Bhajan List], GP_Bhajan_List[Singer]),"")} | D4: Jaya Devi Bhavani Ma | G4: 1.5 Pancham / C# | H4: {=IFNA(INDEX(Pitches[],MATCH($G4,Pitches[Pitches],0),2),"")} -> G# | I4: {=IF( AND(D4="", E4=""), "", IFNA( IF( INDEX(Singers[], MATCH(IF(D4<>"", B4, C4), Singers[Singers], 0), 2, 0) = "Gents", INDEX(Bhajans[], MATCH(IF(D4<>"", D4, E4), Bhajans[title], 0), 13), INDEX(Bhajans[], MATCH(IF(D4<>"", D4, E4), Bhajans[title], 0), 14) ), "" ) )} -> 1.5 Pancham / C# | J4: {=IF(AND($D4="", $E4=""), "", IFNA(INDEX(Bhajans[], MATCH(IF($D4<>"", $D4, $E4), Bhajans[title], 0), 9), ""))} -> ~ Shankarabharanam / Bilawal | K4: {=IF(AND($D4="", $E4=""), "", IFNA(INDEX(Bhajans[], MATCH(IF($D4<>"", $D4, $E4), Bhajans[title], 0), 5), ""))} -> Jaya Devi Bhavani Ma Jaya Sai Bhavani Ma [ Jaya Devi ... ] Jagadeeshwari Sai Ma Parameshwari Sai Ma Jaya Sai Bhavani Ma Jaya Parthi Nivasini Ma (2) | L4: {=IF(AND($D4="", $E4=""), "", IFNA(INDEX(Bhajans[], MATCH(IF($D4<>"", $D4, $E4), Bhajans[title], 0), 4), ""))} -> Victory to Goddess Bhavani, the very existence. Victory to Divine Mother Sathya Sai, the eternal one who rules over the entire universe. Puttaparthi is Her divine abode.
A5: 45734 | B5: Prasanna | C5: {=IFNA(XLOOKUP(E5,GP_Bhajan_List[GP Bhajan List], GP_Bhajan_List[Singer]),"")} | D5: Gopala Radha Lola | G5: 1 Pancham / C | H5: {=IFNA(INDEX(Pitches[],MATCH($G5,Pitches[Pitches],0),2),"")} -> G | I5: {=IF( AND(D5="", E5=""), "", IFNA( IF( INDEX(Singers[], MATCH(IF(D5<>"", B5, C5), Singers[Singers], 0), 2, 0) = "Gents", INDEX(Bhajans[], MATCH(IF(D5<>"", D5, E5), Bhajans[title], 0), 13), INDEX(Bhajans[], MATCH(IF(D5<>"", D5, E5), Bhajans[title], 0), 14) ), "" ) )} -> 1 Pancham / C | J5: {=IF(AND($D5="", $E5=""), "", IFNA(INDEX(Bhajans[], MATCH(IF($D5<>"", $D5, $E5), Bhajans[title], 0), 9), ""))} -> Maand | K5: {=IF(AND($D5="", $E5=""), "", IFNA(INDEX(Bhajans[], MATCH(IF($D5<>"", $D5, $E5), Bhajans[title], 0), 5), ""))} -> Gopala Radha Lola Murali Lola Nandalala [ Gopala ... ] Keshava Madhava Janardhana Vanamala Brindavana Bala [ Murali Lola ... ] Gopala, Hijo De Nanda Dulce Es Tu Flauta Hazla Cantar Keshava, Libranos De La Maldad Santo Eres Senor De Brindavan Toca Tu Flauta, Hazme Sonar | L5: {=IF(AND($D5="", $E5=""), "", IFNA(INDEX(Bhajans[], MATCH(IF($D5<>"", $D5, $E5), Bhajans[title], 0), 4), ""))} -> Chant the name of Gopala, who gives joy to Radha, who is the son of Nanda. He is the one who played the flute, who is also known as Keshava, Madhava and Janardhana. He is the sweet child of Brindavan who wears the garland made of jungle flowers.
A6: 45735 | B6: Prasanna | C6: {=IFNA(XLOOKUP(E6,GP_Bhajan_List[GP Bhajan List], GP_Bhajan_List[Singer]),"")} | D6: Gajanana Gajanana (Hamir Kalyani / Kedar) | G6: 7 Pancham / B | H6: {=IFNA(INDEX(Pitches[],MATCH($G6,Pitches[Pitches],0),2),"")} -> F# | I6: {=IF( AND(D6="", E6=""), "", IFNA( IF( INDEX(Singers[], MATCH(IF(D6<>"", B6, C6), Singers[Singers], 0), 2, 0) = "Gents", INDEX(Bhajans[], MATCH(IF(D6<>"", D6, E6), Bhajans[title], 0), 13), INDEX(Bhajans[], MATCH(IF(D6<>"", D6, E6), Bhajans[title], 0), 14) ), "" ) )} -> 6.5 Pancham / A# | J6: {=IF(AND($D6="", $E6=""), "", IFNA(INDEX(Bhajans[], MATCH(IF($D6<>"", $D6, $E6), Bhajans[title], 0), 9), ""))} -> Hamir Kalyani / Kedar | K6: {=IF(AND($D6="", $E6=""), "", IFNA(INDEX(Bhajans[], MATCH(IF($D6<>"", $D6, $E6), Bhajans[title], 0), 5), ""))} -> Gajanana Gajanana Prathama Poojana Ganaraya [ Gajanana ... ] Prathama Prarthana Sri Ganaraya Lambodhara Ganaraya | L6: {=IF(AND($D6="", $E6=""), "", IFNA(INDEX(Bhajans[], MATCH(IF($D6<>"", $D6, $E6), Bhajans[title], 0), 4), ""))} -> O Lord Ganesha, the elephant-faced one, You are the one whom all worship and pray. You are the one to whom the first prostrations should be offered. O Ganaraya, the controller of all the Ganaas (the Demigods), we offer You our first obeisance. O mighty one, You are the King of the Divine Forces.
A7: 45735 | B7: Sailavan | C7: {=IFNA(XLOOKUP(E7,GP_Bhajan_List[GP Bhajan List], GP_Bhajan_List[Singer]),"")} | D7: Jai Jai Guru Deva Sri | G7: 1.5 Pancham / C# | H7: {=IFNA(INDEX(Pitches[],MATCH($G7,Pitches[Pitches],0),2),"")} -> G# | I7: {=IF( AND(D7="", E7=""), "", IFNA( IF( INDEX(Singers[], MATCH(IF(D7<>"", B7, C7), Singers[Singers], 0), 2, 0) = "Gents", INDEX(Bhajans[], MATCH(IF(D7<>"", D7, E7), Bhajans[title], 0), 13), INDEX(Bhajans[], MATCH(IF(D7<>"", D7, E7), Bhajans[title], 0), 14) ), "" ) )} -> 1 Pancham / C | J7: {=IF(AND($D7="", $E7=""), "", IFNA(INDEX(Bhajans[], MATCH(IF($D7<>"", $D7, $E7), Bhajans[title], 0), 9), ""))} -> Darbari | K7: {=IF(AND($D7="", $E7=""), "", IFNA(INDEX(Bhajans[], MATCH(IF($D7<>"", $D7, $E7), Bhajans[title], 0), 5), ""))} -> Jai Jai Guru Deva Sri Sai Mahadeva (3) Brahma Vishnu Maheshwara Sai Mahadeva Mata Pitha Guru Deva Sri Sai Mahadeva | L7: {=IF(AND($D7="", $E7=""), "", IFNA(INDEX(Bhajans[], MATCH(IF($D7<>"", $D7, $E7), Bhajans[title], 0), 4), ""))} -> Glory to the revered preceptor Mahadeva, who is the embodiment of Mother, Father, Preceptor and the Trinity Brahma, Vishnu and Maheshwara.
A8: 45735 | B8: Prithvi | C8: {=IFNA(XLOOKUP(E8,GP_Bhajan_List[GP Bhajan List], GP_Bhajan_List[Singer]),"")} | D8: Anatha Bandho Sai Prabho | G8: 1.5 Pancham / C# | H8: {=IFNA(INDEX(Pitches[],MATCH($G8,Pitches[Pitches],0),2),"")} -> G# | I8: {=IF( AND(D8="", E8=""), "", IFNA( IF( INDEX(Singers[], MATCH(IF(D8<>"", B8, C8), Singers[Singers], 0), 2, 0) = "Gents", INDEX(Bhajans[], MATCH(IF(D8<>"", D8, E8), Bhajans[title], 0), 13), INDEX(Bhajans[], MATCH(IF(D8<>"", D8, E8), Bhajans[title], 0), 14) ), "" ) )} -> 1 Pancham / C | J8: {=IF(AND($D8="", $E8=""), "", IFNA(INDEX(Bhajans[], MATCH(IF($D8<>"", $D8, $E8), Bhajans[title], 0), 9), ""))} -> Keeravani | K8: {=IF(AND($D8="", $E8=""), "", IFNA(INDEX(Bhajans[], MATCH(IF($D8<>"", $D8, $E8), Bhajans[title], 0), 5), ""))} -> Anatha Bandho Sai Prabho Aparadha Kshama Karo Sai Prabho Jeeva Yatra Mey Saath Raho Tum Prem Bhakthi Hum Ko Deejo Hrudaya Mandir Se Math Jao Charanamrutha Seva Deejo Prabhu | L8: {=IF(AND($D8="", $E8=""), "", IFNA(INDEX(Bhajans[], MATCH(IF($D8<>"", $D8, $E8), Bhajans[title], 0), 4), ""))} -> Oh Lord Sai! You are the protector and kin of the destitute. Kindly forgive our misdeeds and be with us in our journey of life. Bless us with Divine Love and devotion and be constantly in our thoughts and our hearts, grant us the opportunity to serve Your Lotus feet.
A9: 45736 | B9: Ashwin | C9: {=IFNA(XLOOKUP(E9,GP_Bhajan_List[GP Bhajan List], GP_Bhajan_List[Singer]),"")} | D9: Vighneshwaram Bhajorey Manasa Vighna Haram | G9: 2 Pancham / D | H9: {=IFNA(INDEX(Pitches[],MATCH($G9,Pitches[Pitches],0),2),"")} -> A | I9: {=IF( AND(D9="", E9=""), "", IFNA( IF( INDEX(Singers[], MATCH(IF(D9<>"", B9, C9), Singers[Singers], 0), 2, 0) = "Gents", INDEX(Bhajans[], MATCH(IF(D9<>"", D9, E9), Bhajans[title], 0), 13), INDEX(Bhajans[], MATCH(IF(D9<>"", D9, E9), Bhajans[title], 0), 14) ), "" ) )} -> 3 Pancham / E | J9: {=IF(AND($D9="", $E9=""), "", IFNA(INDEX(Bhajans[], MATCH(IF($D9<>"", $D9, $E9), Bhajans[title], 0), 9), ""))} -> Mayamalavagowla / Bhairav | K9: {=IF(AND($D9="", $E9=""), "", IFNA(INDEX(Bhajans[], MATCH(IF($D9<>"", $D9, $E9), Bhajans[title], 0), 5), ""))} -> Vighneshwaram Bhajorey Manasa Vighna Haram Bhajorey (2) (Bhajorey) Vighneshwaram Bhajorey Manasa Vighna Haram Bhajorey | L9: {=IF(AND($D9="", $E9=""), "", IFNA(INDEX(Bhajans[], MATCH(IF($D9<>"", $D9, $E9), Bhajans[title], 0), 4), ""))} -> Oh Mind! Sing the praises of Lord Vighneshwara (Lord Ganesha) who removes all obstacles and destroys them.
A10: 45736 | B10: Sailavan | C10: {=IFNA(XLOOKUP(E10,GP_Bhajan_List[GP Bhajan List], GP_Bhajan_List[Singer]),"")} | D10: Shrivatsankitha Sri Kaustubha Dhara | G10: 4.5 Pancham / F# | H10: {=IFNA(INDEX(Pitches[],MATCH($G10,Pitches[Pitches],0),2),"")} -> C# | I10: {=IF( AND(D10="", E10=""), "", IFNA( IF( INDEX(Singers[], MATCH(IF(D10<>"", B10, C10), Singers[Singers], 0), 2, 0) = "Gents", INDEX(Bhajans[], MATCH(IF(D10<>"", D10, E10), Bhajans[title], 0), 13), INDEX(Bhajans[], MATCH(IF(D10<>"", D10, E10), Bhajans[title], 0), 14) ), "" ) )} -> 3 Pancham / E | J10: {=IF(AND($D10="", $E10=""), "", IFNA(INDEX(Bhajans[], MATCH(IF($D10<>"", $D10, $E10), Bhajans[title], 0), 9), ""))} -> Panchamkauns / Jayanthashri | K10: {=IF(AND($D10="", $E10=""), "", IFNA(INDEX(Bhajans[], MATCH(IF($D10<>"", $D10, $E10), Bhajans[title], 0), 5), ""))} -> Shrivatsankitha Sri Kaustubha Dhara Madhava Mohana Krishna (2) Sri Tulasi Dala Vanamala Dhara [ Madhava Mohana ... (2) ] Kali Yuga Varada Kali Avatara Karuna Sagara Sai (2) | L10: {=IF(AND($D10="", $E10=""), "", IFNA(INDEX(Bhajans[], MATCH(IF($D10<>"", $D10, $E10), Bhajans[title], 0), 4), ""))} -> Glory to Lord Sai, the compassionate one who is the incarnation of Lord Vishnu in Kali age, who is depicted to be bearing the sign of "Srivatsa" (it symbolizes Vishnu's yogic powers) and the splendorous jewel "Kaustubha" (it represents the consciousness of all living things). He is none other than Lord Krishna wearing the garland of Sacred Tulasi leaves (Basil Leaves).
A11: 45736 | B11: Prithvi | C11: {=IFNA(XLOOKUP(E11,GP_Bhajan_List[GP Bhajan List], GP_Bhajan_List[Singer]),"")} | D11: Baar Baar Tum Aao Sai | G11: 1.5 Pancham / C# | H11: {=IFNA(INDEX(Pitches[],MATCH($G11,Pitches[Pitches],0),2),"")} -> G# | I11: {=IF( AND(D11="", E11=""), "", IFNA( IF( INDEX(Singers[], MATCH(IF(D11<>"", B11, C11), Singers[Singers], 0), 2, 0) = "Gents", INDEX(Bhajans[], MATCH(IF(D11<>"", D11, E11), Bhajans[title], 0), 13), INDEX(Bhajans[], MATCH(IF(D11<>"", D11, E11), Bhajans[title], 0), 14) ), "" ) )} -> 2.5 Pancham / D# | J11: {=IF(AND($D11="", $E11=""), "", IFNA(INDEX(Bhajans[], MATCH(IF($D11<>"", $D11, $E11), Bhajans[title], 0), 9), ""))} -> Hamir Kalyani / Kedar | K11: {=IF(AND($D11="", $E11=""), "", IFNA(INDEX(Bhajans[], MATCH(IF($D11<>"", $D11, $E11), Bhajans[title], 0), 5), ""))} -> Baar Baar Tum Aao Sai Darshana Do Bhagawan (2) Nithya Nirmala Nithyananda Satchidananda Prabho Darshana Do Bhagawan | L11: {=IF(AND($D11="", $E11=""), "", IFNA(INDEX(Bhajans[], MATCH(IF($D11<>"", $D11, $E11), Bhajans[title], 0), 4), ""))} -> Welcome O Lord Sai. Grant us the darshan of Your ever pure and blissful Form again and again.
A12: 45737 | B12: Pavitra | C12: {=IFNA(XLOOKUP(E12,GP_Bhajan_List[GP Bhajan List], GP_Bhajan_List[Singer]),"")} | D12: Matanga Vadana Maam Palaya | G12: 5.5 Madhyam / C# | H12: {=IFNA(INDEX(Pitches[],MATCH($G12,Pitches[Pitches],0),2),"")} -> G# | I12: {=IF( AND(D12="", E12=""), "", IFNA( IF( INDEX(Singers[], MATCH(IF(D12<>"", B12, C12), Singers[Singers], 0), 2, 0) = "Gents", INDEX(Bhajans[], MATCH(IF(D12<>"", D12, E12), Bhajans[title], 0), 13), INDEX(Bhajans[], MATCH(IF(D12<>"", D12, E12), Bhajans[title], 0), 14) ), "" ) )} -> 5 Madhyam / C | J12: {=IF(AND($D12="", $E12=""), "", IFNA(INDEX(Bhajans[], MATCH(IF($D12<>"", $D12, $E12), Bhajans[title], 0), 9), ""))} -> Kuntalavarali | K12: {=IF(AND($D12="", $E12=""), "", IFNA(INDEX(Bhajans[], MATCH(IF($D12<>"", $D12, $E12), Bhajans[title], 0), 5), ""))} -> Matanga Vadana Maam Palaya Mouleeshwara Shiva Gowri Nandana (2) Mangala Dayaka Siddhi Vinayaka | L12: {=IF(AND($D12="", $E12=""), "", IFNA(INDEX(Bhajans[], MATCH(IF($D12<>"", $D12, $E12), Bhajans[title], 0), 4), ""))} -> O elephant-faced Lord Ganesha, protect me. O beloved son of Lord Shiva and Gowri, You are the one who bestows auspiciousness and success in our endeavors.
A13: 45737 | B13: Rhuben | C13: {=IFNA(XLOOKUP(E13,GP_Bhajan_List[GP Bhajan List], GP_Bhajan_List[Singer]),"")} | D13: Shiva Shambho Hara Hara Shambho | G13: 5.5 Pancham / G# | H13: {=IFNA(INDEX(Pitches[],MATCH($G13,Pitches[Pitches],0),2),"")} -> D# | I13: {=IF( AND(D13="", E13=""), "", IFNA( IF( INDEX(Singers[], MATCH(IF(D13<>"", B13, C13), Singers[Singers], 0), 2, 0) = "Gents", INDEX(Bhajans[], MATCH(IF(D13<>"", D13, E13), Bhajans[title], 0), 13), INDEX(Bhajans[], MATCH(IF(D13<>"", D13, E13), Bhajans[title], 0), 14) ), "" ) )} -> 5.5 Pancham / G# | J13: {=IF(AND($D13="", $E13=""), "", IFNA(INDEX(Bhajans[], MATCH(IF($D13<>"", $D13, $E13), Bhajans[title], 0), 9), ""))} -> Shankarabharanam / Bilawal | K13: {=IF(AND($D13="", $E13=""), "", IFNA(INDEX(Bhajans[], MATCH(IF($D13<>"", $D13, $E13), Bhajans[title], 0), 5), ""))} -> Shiva Shambho Hara Hara Shambho Bhava Nasha Kailasa Nivasa [ Shiva Shambho ... ] Parvathi Pathey Harey Pashupathey Gangadhara Hara Gowri Pathey | L13: {=IF(AND($D13="", $E13=""), "", IFNA(INDEX(Bhajans[], MATCH(IF($D13<>"", $D13, $E13), Bhajans[title], 0), 4), ""))} -> O Lord Shiva, You are the destroyer of all fear, the one who resides in the holy mountains of Kailasa, the consort of Mother Parvathi, the one who holds the mighty Ganges in Your matted locks, the consort of Mother Gowri. We pray and offer our humble salutations at Your Feet.
A14: 45737 | B14: Prasanna | C14: {=IFNA(XLOOKUP(E14,GP_Bhajan_List[GP Bhajan List], GP_Bhajan_List[Singer]),"")} | D14: Jai Jai Bhavani Ma Ambe | G14: 1 Pancham / C | H14: {=IFNA(INDEX(Pitches[],MATCH($G14,Pitches[Pitches],0),2),"")} -> G | I14: {=IF( AND(D14="", E14=""), "", IFNA( IF( INDEX(Singers[], MATCH(IF(D14<>"", B14, C14), Singers[Singers], 0), 2, 0) = "Gents", INDEX(Bhajans[], MATCH(IF(D14<>"", D14, E14), Bhajans[title], 0), 13), INDEX(Bhajans[], MATCH(IF(D14<>"", D14, E14), Bhajans[title], 0), 14) ), "" ) )} -> 6 Pancham / A | J14: {=IF(AND($D14="", $E14=""), "", IFNA(INDEX(Bhajans[], MATCH(IF($D14<>"", $D14, $E14), Bhajans[title], 0), 9), ""))} -> Shankarabharanam / Bilawal | K14: {=IF(AND($D14="", $E14=""), "", IFNA(INDEX(Bhajans[], MATCH(IF($D14<>"", $D14, $E14), Bhajans[title], 0), 5), ""))} -> Jai Jai Bhavani Ma Ambe Bhavani Ma Ambe Bhavani Ma Sai Bhavani Ma [ Jai Jai Bhavani ... ] Shirdi Nivasi Ma Parthi Nivasi Ma Hrudaya Nivasi Ma Ambe (Sai) Bhavani Ma Jai Jai Bhavani Ma Ambe Bhavani Ma Ambe Bhavani Ma Sai Bhavani Ma [ Jai Jai Bhavani ... ] Shirdi Bhavani Ma Parthi Nivasi Ma Hrudaya Nivasi Ma Ambe (Sai) Bhavani Ma | L14: {=IF(AND($D14="", $E14=""), "", IFNA(INDEX(Bhajans[], MATCH(IF($D14<>"", $D14, $E14), Bhajans[title], 0), 4), ""))} -> Victory to Divine Mother Parvathi who is hailed as Ambe and Bhavani and who is the indweller of the heart. She is none other than Lord Sai who dwells in Shirdi and Parthi.
A15: 45738 | B15: Jothsna | C15: {=IFNA(XLOOKUP(E15,GP_Bhajan_List[GP Bhajan List], GP_Bhajan_List[Singer]),"")} | D15: Ambika Tanaya Gajanana | G15: 6 Madhyam / D | H15: {=IFNA(INDEX(Pitches[],MATCH($G15,Pitches[Pitches],0),2),"")} -> A | I15: {=IF( AND(D15="", E15=""), "", IFNA( IF( INDEX(Singers[], MATCH(IF(D15<>"", B15, C15), Singers[Singers], 0), 2, 0) = "Gents", INDEX(Bhajans[], MATCH(IF(D15<>"", D15, E15), Bhajans[title], 0), 13), INDEX(Bhajans[], MATCH(IF(D15<>"", D15, E15), Bhajans[title], 0), 14) ), "" ) )} -> 5.5 Madhyam / C# | J15: {=IF(AND($D15="", $E15=""), "", IFNA(INDEX(Bhajans[], MATCH(IF($D15<>"", $D15, $E15), Bhajans[title], 0), 9), ""))} -> Pahadi | K15: {=IF(AND($D15="", $E15=""), "", IFNA(INDEX(Bhajans[], MATCH(IF($D15<>"", $D15, $E15), Bhajans[title], 0), 5), ""))} -> Ambika Tanaya Gajanana Gajavadana Gananatha Gajanana Paahi Ganesha Vinayaka Tribhuvana Palaka Mangala Dayaka Vidya Buddhi Siddhi Pradayaka Paahi Ganesha Vinayaka (2) Ambika Tanaya Vinayaka Gajavadana Gananatha Vinayaka (Sathya) Sai Ganesha Vinayaka Tribhuvana Palaka Mangala Dayaka Vidya Buddhi Siddhi Pradayaka (Sathya) Sai Ganesha Vinayaka | L15: {=IF(AND($D15="", $E15=""), "", IFNA(INDEX(Bhajans[], MATCH(IF($D15<>"", $D15, $E15), Bhajans[title], 0), 4), ""))} -> O loving son of Mother Parvathi, the elephant-headed Lord Ganesha, kindly protect us. You are the sustainer of the three worlds, the one who confers auspiciousness, knowledge, wisdom and success.
... A66: 45776 | B66: Prithvi | C66: {=IFNA(XLOOKUP(E66,GP_Bhajan_List[GP Bhajan List], GP_Bhajan_List[Singer]),"")} | D66: Bhajan Karo Manuva Govinda Harey | G66: 5 Pancham / G | H66: {=IFNA(INDEX(Pitches[],MATCH($G66,Pitches[Pitches],0),2),"")} -> D | I66: {=IF( AND(D66="", E66=""), "", IFNA( IF( INDEX(Singers[], MATCH(IF(D66<>"", B66, C66), Singers[Singers], 0), 2, 0) = "Gents", INDEX(Bhajans[], MATCH(IF(D66<>"", D66, E66), Bhajans[title], 0), 13), INDEX(Bhajans[], MATCH(IF(D66<>"", D66, E66), Bhajans[title], 0), 14) ), "" ) )} -> 4 Pancham / F | J66: {=IF(AND($D66="", $E66=""), "", IFNA(INDEX(Bhajans[], MATCH(IF($D66<>"", $D66, $E66), Bhajans[title], 0), 9), ""))} -> Pilu | K66: {=IF(AND($D66="", $E66=""), "", IFNA(INDEX(Bhajans[], MATCH(IF($D66<>"", $D66, $E66), Bhajans[title], 0), 5), ""))} -> Bhajan Karo Manuva Govinda Harey Govinda Murari Gopala Murari [ Bhajan Karo ... ] Mathura Natha Hey Giridhari Radha Madhava Hey Giridhari (2) | L66: {=IF(AND($D66="", $E66=""), "", IFNA(INDEX(Bhajans[], MATCH(IF($D66<>"", $D66, $E66), Bhajans[title], 0), 4), ""))} -> O mind, worship Lord Krishna, known by many names - Govinda, Murari, Gopala, the Lord of Mathura, Giridhari, the Lord of Radha.
A67: 45777 | B67: Prithvi | C67: {=IFNA(XLOOKUP(E67,GP_Bhajan_List[GP Bhajan List], GP_Bhajan_List[Singer]),"")} | D67: Gajavadana Gananatha Natha (Bilawal) | F67: Bilawal not Sohini - it exists on sai rhythms but not on this | G67: 4.5 Pancham / F# | H67: {=IFNA(INDEX(Pitches[],MATCH($G67,Pitches[Pitches],0),2),"")} -> C# | I67: {=IF( AND(D67="", E67=""), "", IFNA( IF( INDEX(Singers[], MATCH(IF(D67<>"", B67, C67), Singers[Singers], 0), 2, 0) = "Gents", INDEX(Bhajans[], MATCH(IF(D67<>"", D67, E67), Bhajans[title], 0), 13), INDEX(Bhajans[], MATCH(IF(D67<>"", D67, E67), Bhajans[title], 0), 14) ), "" ) )} -> 3 Pancham / E | J67: {=IF(AND($D67="", $E67=""), "", IFNA(INDEX(Bhajans[], MATCH(IF($D67<>"", $D67, $E67), Bhajans[title], 0), 9), ""))} -> Shankarabharanam / Bilawal | K67: {=IF(AND($D67="", $E67=""), "", IFNA(INDEX(Bhajans[], MATCH(IF($D67<>"", $D67, $E67), Bhajans[title], 0), 5), ""))} -> Gajavadana Gananatha Natha Gowri Vara Tanaya Gunaalaya [ Gajavadana ... ] Vidya Dayaka Buddhi Pradayaka Siddhi Vinayaka Hey Shubha Dayaka | L67: {=IF(AND($D67="", $E67=""), "", IFNA(INDEX(Bhajans[], MATCH(IF($D67<>"", $D67, $E67), Bhajans[title], 0), 4), ""))} -> O Ganesha, the elephant-faced Lord, You are the Lord of the Divine Forces. O beloved son of Mother Gowri (Parvathi), You are full of virtues. O bestower of knowledge, intelligence, wisdom and power, You are the conferrer of all auspiciousness.
A68: 45777 | B68: Jothsna | C68: {=IFNA(XLOOKUP(E68,GP_Bhajan_List[GP Bhajan List], GP_Bhajan_List[Singer]),"")} | D68: Dasharatha Nandana Rama Daya Sagara | G68: 7 Pancham / B | H68: {=IFNA(INDEX(Pitches[],MATCH($G68,Pitches[Pitches],0),2),"")} -> F# | I68: {=IF( AND(D68="", E68=""), "", IFNA( IF( INDEX(Singers[], MATCH(IF(D68<>"", B68, C68), Singers[Singers], 0), 2, 0) = "Gents", INDEX(Bhajans[], MATCH(IF(D68<>"", D68, E68), Bhajans[title], 0), 13), INDEX(Bhajans[], MATCH(IF(D68<>"", D68, E68), Bhajans[title], 0), 14) ), "" ) )} | J68: {=IF(AND($D68="", $E68=""), "", IFNA(INDEX(Bhajans[], MATCH(IF($D68<>"", $D68, $E68), Bhajans[title], 0), 9), ""))} | K68: {=IF(AND($D68="", $E68=""), "", IFNA(INDEX(Bhajans[], MATCH(IF($D68<>"", $D68, $E68), Bhajans[title], 0), 5), ""))} | L68: {=IF(AND($D68="", $E68=""), "", IFNA(INDEX(Bhajans[], MATCH(IF($D68<>"", $D68, $E68), Bhajans[title], 0), 4), ""))}
A69: 45777 | B69: Ashwin | C69: {=IFNA(XLOOKUP(E69,GP_Bhajan_List[GP Bhajan List], GP_Bhajan_List[Singer]),"")} | D69: Madhuvana Sanchari Shyama Murari | G69: 5 Pancham / G | H69: {=IFNA(INDEX(Pitches[],MATCH($G69,Pitches[Pitches],0),2),"")} -> D | I69: {=IF( AND(D69="", E69=""), "", IFNA( IF( INDEX(Singers[], MATCH(IF(D69<>"", B69, C69), Singers[Singers], 0), 2, 0) = "Gents", INDEX(Bhajans[], MATCH(IF(D69<>"", D69, E69), Bhajans[title], 0), 13), INDEX(Bhajans[], MATCH(IF(D69<>"", D69, E69), Bhajans[title], 0), 14) ), "" ) )} -> 2 Madhyam / G | J69: {=IF(AND($D69="", $E69=""), "", IFNA(INDEX(Bhajans[], MATCH(IF($D69<>"", $D69, $E69), Bhajans[title], 0), 9), ""))} -> Mishra Rageshri | K69: {=IF(AND($D69="", $E69=""), "", IFNA(INDEX(Bhajans[], MATCH(IF($D69<>"", $D69, $E69), Bhajans[title], 0), 5), ""))} -> Madhuvana Sanchari Shyama Murari Sri Madhusudhana Muralidhari [ Madhuvana Sanchari ... ] Madhava Mohana Mayura Mukutadhara Mathura Natha Prabhu (Sai) Giridhari | L69: {=IF(AND($D69="", $E69=""), "", IFNA(INDEX(Bhajans[], MATCH(IF($D69<>"", $D69, $E69), Bhajans[title], 0), 4), ""))} -> Glory to You, Lord Krishna. You are the slayer of demon Mura and the one who moved about in the forest of demon Madhu to slay him. You have worn the feather of the Peacock on Your head and is the Lord of Mathura who lifted the Govardhana mountain.
A70: 45778 | B70: Pavitra | C70: {=IFNA(XLOOKUP(E70,GP_Bhajan_List[GP Bhajan List], GP_Bhajan_List[Singer]),"")} | D70: Gajamukha Gajamukha Gananatha | G70: 5 Pancham / G | H70: {=IFNA(INDEX(Pitches[],MATCH($G70,Pitches[Pitches],0),2),"")} -> D | I70: {=IF( AND(D70="", E70=""), "", IFNA( IF( INDEX(Singers[], MATCH(IF(D70<>"", B70, C70), Singers[Singers], 0), 2, 0) = "Gents", INDEX(Bhajans[], MATCH(IF(D70<>"", D70, E70), Bhajans[title], 0), 13), INDEX(Bhajans[], MATCH(IF(D70<>"", D70, E70), Bhajans[title], 0), 14) ), "" ) )} -> 5 Pancham / G | J70: {=IF(AND($D70="", $E70=""), "", IFNA(INDEX(Bhajans[], MATCH(IF($D70<>"", $D70, $E70), Bhajans[title], 0), 9), ""))} -> Nattai | K70: {=IF(AND($D70="", $E70=""), "", IFNA(INDEX(Bhajans[], MATCH(IF($D70<>"", $D70, $E70), Bhajans[title], 0), 5), ""))} -> Gajamukha Gajamukha Gananatha Suramuni Vanditha Guna Sheela [ Gajamukha ... ] Suramuni Vanditha Guna Sheela Gajamukha Gajamukha Gananatha [ Suramuni ... ] | L70: {=IF(AND($D70="", $E70=""), "", IFNA(INDEX(Bhajans[], MATCH(IF($D70<>"", $D70, $E70), Bhajans[title], 0), 4), ""))} -> We chant the glory of Gajamukha, the elephant faced Lord Ganesha, who is the leader of Ganaas (demigods), who is worshipped by the sages and noble people and who is the embodiment of virtues.
A71: 45778 | B71: Jothsna | C71: {=IFNA(XLOOKUP(E71,GP_Bhajan_List[GP Bhajan List], GP_Bhajan_List[Singer]),"")} | D71: Govinda Harey Gopala Harey | G71: 6 Pancham / A | H71: {=IFNA(INDEX(Pitches[],MATCH($G71,Pitches[Pitches],0),2),"")} -> E | I71: {=IF( AND(D71="", E71=""), "", IFNA( IF( INDEX(Singers[], MATCH(IF(D71<>"", B71, C71), Singers[Singers], 0), 2, 0) = "Gents", INDEX(Bhajans[], MATCH(IF(D71<>"", D71, E71), Bhajans[title], 0), 13), INDEX(Bhajans[], MATCH(IF(D71<>"", D71, E71), Bhajans[title], 0), 14) ), "" ) )} | J71: {=IF(AND($D71="", $E71=""), "", IFNA(INDEX(Bhajans[], MATCH(IF($D71<>"", $D71, $E71), Bhajans[title], 0), 9), ""))} | K71: {=IF(AND($D71="", $E71=""), "", IFNA(INDEX(Bhajans[], MATCH(IF($D71<>"", $D71, $E71), Bhajans[title], 0), 5), ""))} | L71: {=IF(AND($D71="", $E71=""), "", IFNA(INDEX(Bhajans[], MATCH(IF($D71<>"", $D71, $E71), Bhajans[title], 0), 4), ""))}
A72: 45778 | B72: Prithvi | C72: {=IFNA(XLOOKUP(E72,GP_Bhajan_List[GP Bhajan List], GP_Bhajan_List[Singer]),"")} | D72: Hara Hara Hara Hara Samba | G72: 3 Pancham / E | H72: {=IFNA(INDEX(Pitches[],MATCH($G72,Pitches[Pitches],0),2),"")} -> B | I72: {=IF( AND(D72="", E72=""), "", IFNA( IF( INDEX(Singers[], MATCH(IF(D72<>"", B72, C72), Singers[Singers], 0), 2, 0) = "Gents", INDEX(Bhajans[], MATCH(IF(D72<>"", D72, E72), Bhajans[title], 0), 13), INDEX(Bhajans[], MATCH(IF(D72<>"", D72, E72), Bhajans[title], 0), 14) ), "" ) )} -> 2 Pancham / D | J72: {=IF(AND($D72="", $E72=""), "", IFNA(INDEX(Bhajans[], MATCH(IF($D72<>"", $D72, $E72), Bhajans[title], 0), 9), ""))} -> Mohanam / Bhoop | K72: {=IF(AND($D72="", $E72=""), "", IFNA(INDEX(Bhajans[], MATCH(IF($D72<>"", $D72, $E72), Bhajans[title], 0), 5), ""))} -> Hara Hara Hara Hara Samba Shiva Vibhuti Sundara Sai Shiva Gangadhara Hara Gowri Shiva Trishoola Dhari Trinetra Shiva Parthi Puri Paramesha Shiva [ Vibhuti Sundara ... ] | L72: {=IF(AND($D72="", $E72=""), "", IFNA(INDEX(Bhajans[], MATCH(IF($D72<>"", $D72, $E72), Bhajans[title], 0), 4), ""))} -> Chant the name of Shiva the three-eyed destroyer of evil. He bears the Ganges and the trident; chant the name of Sai Shiva of Parthi Who is adorned with holy ash.
A73: 45783 | B73: Sailavan | C73: {=IFNA(XLOOKUP(E73,GP_Bhajan_List[GP Bhajan List], GP_Bhajan_List[Singer]),"")} | D73: Adi Poojya Deva Gajanana | G73: 1.5 Pancham / C# | H73: {=IFNA(INDEX(Pitches[],MATCH($G73,Pitches[Pitches],0),2),"")} -> G# | I73: {=IF( AND(D73="", E73=""), "", IFNA( IF( INDEX(Singers[], MATCH(IF(D73<>"", B73, C73), Singers[Singers], 0), 2, 0) = "Gents", INDEX(Bhajans[], MATCH(IF(D73<>"", D73, E73), Bhajans[title], 0), 13), INDEX(Bhajans[], MATCH(IF(D73<>"", D73, E73), Bhajans[title], 0), 14) ), "" ) )} -> 1.5 Pancham / C# | J73: {=IF(AND($D73="", $E73=""), "", IFNA(INDEX(Bhajans[], MATCH(IF($D73<>"", $D73, $E73), Bhajans[title], 0), 9), ""))} -> Mishra Gowri Manohari / Patdeep | K73: {=IF(AND($D73="", $E73=""), "", IFNA(INDEX(Bhajans[], MATCH(IF($D73<>"", $D73, $E73), Bhajans[title], 0), 5), ""))} -> Adi Poojya Deva Gajanana Gowrivara Tanaya Shubhanana [ Adi Poojya ... ] Vighna Vinashaka Siddhi Vinayaka Jaya Jagavandana Tava Charanam | L73: {=IF(AND($D73="", $E73=""), "", IFNA(INDEX(Bhajans[], MATCH(IF($D73<>"", $D73, $E73), Bhajans[title], 0), 4), ""))} -> At the outset, worship Lord Ganesha, son of Mother Gowri who bestows good fortune. He destroys difficulties and grants success. The entire Universe worships His Feet.
A74: 45783 | B74: Sriraag | C74: {=IFNA(XLOOKUP(E74,GP_Bhajan_List[GP Bhajan List], GP_Bhajan_List[Singer]),"")} | D74: Guru Devaya Namo Namo | G74: 1.5 Pancham / C# | H74: {=IFNA(INDEX(Pitches[],MATCH($G74,Pitches[Pitches],0),2),"")} -> G# | I74: {=IF( AND(D74="", E74=""), "", IFNA( IF( INDEX(Singers[], MATCH(IF(D74<>"", B74, C74), Singers[Singers], 0), 2, 0) = "Gents", INDEX(Bhajans[], MATCH(IF(D74<>"", D74, E74), Bhajans[title], 0), 13), INDEX(Bhajans[], MATCH(IF(D74<>"", D74, E74), Bhajans[title], 0), 14) ), "" ) )} -> 1.5 Pancham / C# | J74: {=IF(AND($D74="", $E74=""), "", IFNA(INDEX(Bhajans[], MATCH(IF($D74<>"", $D74, $E74), Bhajans[title], 0), 9), ""))} -> Kalyani / Yaman | K74: {=IF(AND($D74="", $E74=""), "", IFNA(INDEX(Bhajans[], MATCH(IF($D74<>"", $D74, $E74), Bhajans[title], 0), 5), ""))} -> Guru Devaya Namo Namo Hey Parameshwara Namo Namo [ Guru Devaya ... ] Omkaraya Namo Namo Parthi Pureeshwara Namo Namo Jagadeeshwaraya Namo Namo Prashanthi Eshwara Namo Namo | L74: {=IF(AND($D74="", $E74=""), "", IFNA(INDEX(Bhajans[], MATCH(IF($D74<>"", $D74, $E74), Bhajans[title], 0), 4), ""))} -> Salutations to the Supreme Noble Teacher, Lord Sai, the Supreme Lord, the Lord whose form is Om, the Lord of Prashanthi Nilayam at Puttaparthi and the Lord of the Universe.
A75: 45783 | B75: Ashwin | C75: {=IFNA(XLOOKUP(E75,GP_Bhajan_List[GP Bhajan List], GP_Bhajan_List[Singer]),"")} | D75: Dhanya Ho Eshwaramba | G75: 1 Pancham / C | H75: {=IFNA(INDEX(Pitches[],MATCH($G75,Pitches[Pitches],0),2),"")} -> G | I75: {=IF( AND(D75="", E75=""), "", IFNA( IF( INDEX(Singers[], MATCH(IF(D75<>"", B75, C75), Singers[Singers], 0), 2, 0) = "Gents", INDEX(Bhajans[], MATCH(IF(D75<>"", D75, E75), Bhajans[title], 0), 13), INDEX(Bhajans[], MATCH(IF(D75<>"", D75, E75), Bhajans[title], 0), 14) ), "" ) )} -> 1 Pancham / C | J75: {=IF(AND($D75="", $E75=""), "", IFNA(INDEX(Bhajans[], MATCH(IF($D75<>"", $D75, $E75), Bhajans[title], 0), 9), ""))} -> Sindhu Bhairavi / Bhairavi | K75: {=IF(AND($D75="", $E75=""), "", IFNA(INDEX(Bhajans[], MATCH(IF($D75<>"", $D75, $E75), Bhajans[title], 0), 5), ""))} -> Dhanya Ho Eshwaramba Jag Ko Deejo Lal Baba Dhanya Ho Dhanya Ho Kali Yug Mey Avatar Liye Sakala Charachara Ke Bhagawan Jagadodhara Sai Narayana Dhanya Ho Dhanya Ho Dhanya Ho Eshwaramba (2) | L75: {=IF(AND($D75="", $E75=""), "", IFNA(INDEX(Bhajans[], MATCH(IF($D75<>"", $D75, $E75), Bhajans[title], 0), 4), ""))} -> Glory to Thee, O auspicious Mother Eshwaramba, You have gifted Lord Sai to the world in the present Kali age. Lord Sai is verily Lord Narayana who is omnipresent and has come for the deliverance of mankind.
A76: 45784 | B76: Shravya | C76: {=IFNA(XLOOKUP(E76,GP_Bhajan_List[GP Bhajan List], GP_Bhajan_List[Singer]),"")} | D76: Jai Ganesha Paahi Maam Sri | G76: 1.5 Pancham / C# | H76: {=IFNA(INDEX(Pitches[],MATCH($G76,Pitches[Pitches],0),2),"")} -> G# | I76: {=IF( AND(D76="", E76=""), "", IFNA( IF( INDEX(Singers[], MATCH(IF(D76<>"", B76, C76), Singers[Singers], 0), 2, 0) = "Gents", INDEX(Bhajans[], MATCH(IF(D76<>"", D76, E76), Bhajans[title], 0), 13), INDEX(Bhajans[], MATCH(IF(D76<>"", D76, E76), Bhajans[title], 0), 14) ), "" ) )} -> 1 Pancham / C | J76: {=IF(AND($D76="", $E76=""), "", IFNA(INDEX(Bhajans[], MATCH(IF($D76<>"", $D76, $E76), Bhajans[title], 0), 9), ""))} -> Pahadi | K76: {=IF(AND($D76="", $E76=""), "", IFNA(INDEX(Bhajans[], MATCH(IF($D76<>"", $D76, $E76), Bhajans[title], 0), 5), ""))} -> Jai Ganesha Paahi Maam Sri Ganesha Raksha Maam Jai Ganesh Jai Ganesh Jai Ganesha Raksha Maam Lambodhara Gowri Sutha Jai Ganesha Paahi Maam Mangala Kara Sankata Hara Jai Ganesha Raksha Maam [ Jai Ganesh Jai Ganesh ...] | L76: {=IF(AND($D76="", $E76=""), "", IFNA(INDEX(Bhajans[], MATCH(IF($D76<>"", $D76, $E76), Bhajans[title], 0), 4), ""))} -> Save me Lord Ganesh, the one with a big belly and the son of Mother Gowri. Protect me O Lord Ganesh, for You destroy the plighted condition of Your devotees and confer prosperity and auspiciousness.
A77: 45784 | B77: Prasanna | C77: {=IFNA(XLOOKUP(E77,GP_Bhajan_List[GP Bhajan List], GP_Bhajan_List[Singer]),"")} | D77: Rama Krishna Vasudeva Narayana Hari | G77: 2.5 Pancham / D# | H77: {=IFNA(INDEX(Pitches[],MATCH($G77,Pitches[Pitches],0),2),"")} -> A# | I77: {=IF( AND(D77="", E77=""), "", IFNA( IF( INDEX(Singers[], MATCH(IF(D77<>"", B77, C77), Singers[Singers], 0), 2, 0) = "Gents", INDEX(Bhajans[], MATCH(IF(D77<>"", D77, E77), Bhajans[title], 0), 13), INDEX(Bhajans[], MATCH(IF(D77<>"", D77, E77), Bhajans[title], 0), 14) ), "" ) )} -> 2.5 Pancham / D# | J77: {=IF(AND($D77="", $E77=""), "", IFNA(INDEX(Bhajans[], MATCH(IF($D77<>"", $D77, $E77), Bhajans[title], 0), 9), ""))} -> Shankarabharanam / Bilawal | K77: {=IF(AND($D77="", $E77=""), "", IFNA(INDEX(Bhajans[], MATCH(IF($D77<>"", $D77, $E77), Bhajans[title], 0), 5), ""))} -> Rama Krishna Vasudeva Narayana Hari Hari Vishwa Roopa Vasudeva Narayana Hari Hari Narayana Hari Hari Om Narayana Hari Hari [ Vishwa Roopa ... ] | L77: {=IF(AND($D77="", $E77=""), "", IFNA(INDEX(Bhajans[], MATCH(IF($D77<>"", $D77, $E77), Bhajans[title], 0), 4), ""))} -> Chant the names of Lord Rama, Krishna, Vasudeva, Hari, Narayana, the all-pervading cosmic form of the Lord of Lords, Lord Hari, who is verily Lord Sai.
A78: 45784 | B78: Prithvi | C78: {=IFNA(XLOOKUP(E78,GP_Bhajan_List[GP Bhajan List], GP_Bhajan_List[Singer]),"")} | D78: Jaya Kausalya Nandana Ram Paramananda | G78: 5.5 Pancham / G# | H78: {=IFNA(INDEX(Pitches[],MATCH($G78,Pitches[Pitches],0),2),"")} -> D# | I78: {=IF( AND(D78="", E78=""), "", IFNA( IF( INDEX(Singers[], MATCH(IF(D78<>"", B78, C78), Singers[Singers], 0), 2, 0) = "Gents", INDEX(Bhajans[], MATCH(IF(D78<>"", D78, E78), Bhajans[title], 0), 13), INDEX(Bhajans[], MATCH(IF(D78<>"", D78, E78), Bhajans[title], 0), 14) ), "" ) )} -> 2 Madhyam / G | J78: {=IF(AND($D78="", $E78=""), "", IFNA(INDEX(Bhajans[], MATCH(IF($D78<>"", $D78, $E78), Bhajans[title], 0), 9), ""))} -> Pahadi | K78: {=IF(AND($D78="", $E78=""), "", IFNA(INDEX(Bhajans[], MATCH(IF($D78<>"", $D78, $E78), Bhajans[title], 0), 5), ""))} -> Jaya Kausalya Nandana Ram Paramananda Ananda Ram Jaya Shirdeesha Partheesha Ram Jaya Prashanthi Sayeesha Ram [ Jaya Kausalya ... ] Mangala Pavana Naam Jaya Sundara Vaidehi Ram Sundara Sayeesha Ram ( Jaya ) | L78: {=IF(AND($D78="", $E78=""), "", IFNA(INDEX(Bhajans[], MATCH(IF($D78<>"", $D78, $E78), Bhajans[title], 0), 4), ""))} -> Glory to the son of Kausalya, One of Supreme Bliss, who dwells in Shirdi and Prashanthi Nilayam in Parthi. The Name 'Ram' is supremely Auspicious and He is the beloved of Mother Vaidehi (Sita).
A79: 45785 | B79: Ashwin | C79: {=IFNA(XLOOKUP(E79,GP_Bhajan_List[GP Bhajan List], GP_Bhajan_List[Singer]),"")} | D79: Rama Sumira Man Rama Sumira | G79: 1.5 Pancham / C# | H79: {=IFNA(INDEX(Pitches[],MATCH($G79,Pitches[Pitches],0),2),"")} -> G# | I79: {=IF( AND(D79="", E79=""), "", IFNA( IF( INDEX(Singers[], MATCH(IF(D79<>"", B79, C79), Singers[Singers], 0), 2, 0) = "Gents", INDEX(Bhajans[], MATCH(IF(D79<>"", D79, E79), Bhajans[title], 0), 13), INDEX(Bhajans[], MATCH(IF(D79<>"", D79, E79), Bhajans[title], 0), 14) ), "" ) )} -> 1 Pancham / C | J79: {=IF(AND($D79="", $E79=""), "", IFNA(INDEX(Bhajans[], MATCH(IF($D79<>"", $D79, $E79), Bhajans[title], 0), 9), ""))} -> Shankarabharanam / Bilawal | K79: {=IF(AND($D79="", $E79=""), "", IFNA(INDEX(Bhajans[], MATCH(IF($D79<>"", $D79, $E79), Bhajans[title], 0), 5), ""))} -> Rama Sumira Man Rama Sumira Man Rama Sumira Man Ram Janaki Vallabha Dasharatha Nandana Ramachandra Sri Ram Bhaja Mana Sita Ram Ram Bhaja Mana Sita Ram Bhaja Mana Radhey Shyam Shyam Bhaja Mana Radhey Shyam Bhaja Mana Sai Ram Ram Bhaja Mana Sai Ram | L79: {=IF(AND($D79="", $E79=""), "", IFNA(INDEX(Bhajans[], MATCH(IF($D79<>"", $D79, $E79), Bhajans[title], 0), 4), ""))} -> O mind, chant the name of Lord Rama, the beloved of Sita and the son of King Dasharatha. Worship, O mind, Lord Rama, Lord Krishna and Lord Sai.
... A102: 45800 | B102: Prasanna | C102: {=IFNA(XLOOKUP(E102,GP_Bhajan_List[GP Bhajan List], GP_Bhajan_List[Singer]),"")} | D102: Madura Puri Nilayey Meenakshi | G102: 6 Pancham / A | H102: {=IFNA(INDEX(Pitches[],MATCH($G102,Pitches[Pitches],0),2),"")} -> E | I102: {=IF( AND(D102="", E102=""), "", IFNA( IF( INDEX(Singers[], MATCH(IF(D102<>"", B102, C102), Singers[Singers], 0), 2, 0) = "Gents", INDEX(Bhajans[], MATCH(IF(D102<>"", D102, E102), Bhajans[title], 0), 13), INDEX(Bhajans[], MATCH(IF(D102<>"", D102, E102), Bhajans[title], 0), 14) ), "" ) )} -> 1 Pancham / C | J102: {=IF(AND($D102="", $E102=""), "", IFNA(INDEX(Bhajans[], MATCH(IF($D102<>"", $D102, $E102), Bhajans[title], 0), 9), ""))} -> Kanada | K102: {=IF(AND($D102="", $E102=""), "", IFNA(INDEX(Bhajans[], MATCH(IF($D102<>"", $D102, $E102), Bhajans[title], 0), 5), ""))} -> Madura Puri Nilayey Meenakshi Kamakoti Nilayey Kamakshi [ Madura Puri ... ] Kashi Puradheeshwari Vishweshwari Parthi Puradheeshwari Sayeeshwari | L102: {=IF(AND($D102="", $E102=""), "", IFNA(INDEX(Bhajans[], MATCH(IF($D102<>"", $D102, $E102), Bhajans[title], 0), 4), ""))} -> Goddess Meenakshi has Her Abode in Madurai while Kamakshi has Her Abode in Kancheepuram, Vishweshwari has Her Abode in Kashi and Sayeeshwari has Her Abode in Parthi.
A103: 45800 | B103: Jothsna | C103: {=IFNA(XLOOKUP(E103,GP_Bhajan_List[GP Bhajan List], GP_Bhajan_List[Singer]),"")} | H103: {=IFNA(INDEX(Pitches[],MATCH($G103,Pitches[Pitches],0),2),"")} | I103: {=IF( AND(D103="", E103=""), "", IFNA( IF( INDEX(Singers[], MATCH(IF(D103<>"", B103, C103), Singers[Singers], 0), 2, 0) = "Gents", INDEX(Bhajans[], MATCH(IF(D103<>"", D103, E103), Bhajans[title], 0), 13), INDEX(Bhajans[], MATCH(IF(D103<>"", D103, E103), Bhajans[title], 0), 14) ), "" ) )} | J103: {=IF(AND($D103="", $E103=""), "", IFNA(INDEX(Bhajans[], MATCH(IF($D103<>"", $D103, $E103), Bhajans[title], 0), 9), ""))} | K103: {=IF(AND($D103="", $E103=""), "", IFNA(INDEX(Bhajans[], MATCH(IF($D103<>"", $D103, $E103), Bhajans[title], 0), 5), ""))} | L103: {=IF(AND($D103="", $E103=""), "", IFNA(INDEX(Bhajans[], MATCH(IF($D103<>"", $D103, $E103), Bhajans[title], 0), 4), ""))}
A104: 45802 | C104: {=IFNA(XLOOKUP(E104,GP_Bhajan_List[GP Bhajan List], GP_Bhajan_List[Singer]),"")} | H104: {=IFNA(INDEX(Pitches[],MATCH($G104,Pitches[Pitches],0),2),"")} | I104: {=IF( AND(D104="", E104=""), "", IFNA( IF( INDEX(Singers[], MATCH(IF(D104<>"", B104, C104), Singers[Singers], 0), 2, 0) = "Gents", INDEX(Bhajans[], MATCH(IF(D104<>"", D104, E104), Bhajans[title], 0), 13), INDEX(Bhajans[], MATCH(IF(D104<>"", D104, E104), Bhajans[title], 0), 14) ), "" ) )} | J104: {=IF(AND($D104="", $E104=""), "", IFNA(INDEX(Bhajans[], MATCH(IF($D104<>"", $D104, $E104), Bhajans[title], 0), 9), ""))} | K104: {=IF(AND($D104="", $E104=""), "", IFNA(INDEX(Bhajans[], MATCH(IF($D104<>"", $D104, $E104), Bhajans[title], 0), 5), ""))} | L104: {=IF(AND($D104="", $E104=""), "", IFNA(INDEX(Bhajans[], MATCH(IF($D104<>"", $D104, $E104), Bhajans[title], 0), 4), ""))}
A105: 45802 | C105: {=IFNA(XLOOKUP(E105,GP_Bhajan_List[GP Bhajan List], GP_Bhajan_List[Singer]),"")} | H105: {=IFNA(INDEX(Pitches[],MATCH($G105,Pitches[Pitches],0),2),"")} | I105: {=IF( AND(D105="", E105=""), "", IFNA( IF( INDEX(Singers[], MATCH(IF(D105<>"", B105, C105), Singers[Singers], 0), 2, 0) = "Gents", INDEX(Bhajans[], MATCH(IF(D105<>"", D105, E105), Bhajans[title], 0), 13), INDEX(Bhajans[], MATCH(IF(D105<>"", D105, E105), Bhajans[title], 0), 14) ), "" ) )} | J105: {=IF(AND($D105="", $E105=""), "", IFNA(INDEX(Bhajans[], MATCH(IF($D105<>"", $D105, $E105), Bhajans[title], 0), 9), ""))} | K105: {=IF(AND($D105="", $E105=""), "", IFNA(INDEX(Bhajans[], MATCH(IF($D105<>"", $D105, $E105), Bhajans[title], 0), 5), ""))} | L105: {=IF(AND($D105="", $E105=""), "", IFNA(INDEX(Bhajans[], MATCH(IF($D105<>"", $D105, $E105), Bhajans[title], 0), 4), ""))}
A106: 45802 | C106: {=IFNA(XLOOKUP(E106,GP_Bhajan_List[GP Bhajan List], GP_Bhajan_List[Singer]),"")} | H106: {=IFNA(INDEX(Pitches[],MATCH($G106,Pitches[Pitches],0),2),"")} | I106: {=IF( AND(D106="", E106=""), "", IFNA( IF( INDEX(Singers[], MATCH(IF(D106<>"", B106, C106), Singers[Singers], 0), 2, 0) = "Gents", INDEX(Bhajans[], MATCH(IF(D106<>"", D106, E106), Bhajans[title], 0), 13), INDEX(Bhajans[], MATCH(IF(D106<>"", D106, E106), Bhajans[title], 0), 14) ), "" ) )} | J106: {=IF(AND($D106="", $E106=""), "", IFNA(INDEX(Bhajans[], MATCH(IF($D106<>"", $D106, $E106), Bhajans[title], 0), 9), ""))} | K106: {=IF(AND($D106="", $E106=""), "", IFNA(INDEX(Bhajans[], MATCH(IF($D106<>"", $D106, $E106), Bhajans[title], 0), 5), ""))} | L106: {=IF(AND($D106="", $E106=""), "", IFNA(INDEX(Bhajans[], MATCH(IF($D106<>"", $D106, $E106), Bhajans[title], 0), 4), ""))}
A107: 45802 | C107: {=IFNA(XLOOKUP(E107,GP_Bhajan_List[GP Bhajan List], GP_Bhajan_List[Singer]),"")} | H107: {=IFNA(INDEX(Pitches[],MATCH($G107,Pitches[Pitches],0),2),"")} | I107: {=IF( AND(D107="", E107=""), "", IFNA( IF( INDEX(Singers[], MATCH(IF(D107<>"", B107, C107), Singers[Singers], 0), 2, 0) = "Gents", INDEX(Bhajans[], MATCH(IF(D107<>"", D107, E107), Bhajans[title], 0), 13), INDEX(Bhajans[], MATCH(IF(D107<>"", D107, E107), Bhajans[title], 0), 14) ), "" ) )} | J107: {=IF(AND($D107="", $E107=""), "", IFNA(INDEX(Bhajans[], MATCH(IF($D107<>"", $D107, $E107), Bhajans[title], 0), 9), ""))} | K107: {=IF(AND($D107="", $E107=""), "", IFNA(INDEX(Bhajans[], MATCH(IF($D107<>"", $D107, $E107), Bhajans[title], 0), 5), ""))} | L107: {=IF(AND($D107="", $E107=""), "", IFNA(INDEX(Bhajans[], MATCH(IF($D107<>"", $D107, $E107), Bhajans[title], 0), 4), ""))}
A108: 45804 | B108: Ashwin | C108: {=IFNA(XLOOKUP(E108,GP_Bhajan_List[GP Bhajan List], GP_Bhajan_List[Singer]),"")} | D108: Lambodhara Hey Vinayaka | G108: 2 Pancham / D | H108: {=IFNA(INDEX(Pitches[],MATCH($G108,Pitches[Pitches],0),2),"")} -> A | I108: {=IF( AND(D108="", E108=""), "", IFNA( IF( INDEX(Singers[], MATCH(IF(D108<>"", B108, C108), Singers[Singers], 0), 2, 0) = "Gents", INDEX(Bhajans[], MATCH(IF(D108<>"", D108, E108), Bhajans[title], 0), 13), INDEX(Bhajans[], MATCH(IF(D108<>"", D108, E108), Bhajans[title], 0), 14) ), "" ) )} -> 2 Pancham / D | J108: {=IF(AND($D108="", $E108=""), "", IFNA(INDEX(Bhajans[], MATCH(IF($D108<>"", $D108, $E108), Bhajans[title], 0), 9), ""))} -> Shuddha Saveri / Durga | K108: {=IF(AND($D108="", $E108=""), "", IFNA(INDEX(Bhajans[], MATCH(IF($D108<>"", $D108, $E108), Bhajans[title], 0), 5), ""))} -> Lambodhara Hey Vinayaka Vighna Harana Girija Nandana Shambhu Kumara Kalusha Vidhura Siddhi Sadana Hey Gananatha Pranavakaara Pashupathi Tanaya [ Vighna Harana ... ] | L108: {=IF(AND($D108="", $E108=""), "", IFNA(INDEX(Bhajans[], MATCH(IF($D108<>"", $D108, $E108), Bhajans[title], 0), 4), ""))} -> Glory be to the Lord of the Ganas, Lord Ganesha, the remover of obstacles, son of Mother Parvathi and Lord Shiva, one who removes our impurities and bestows us with power and wisdom, the very embodiment of the Pranava (Om).
A109: 45804 | B109: Sriraag | C109: {=IFNA(XLOOKUP(E109,GP_Bhajan_List[GP Bhajan List], GP_Bhajan_List[Singer]),"")} | D109: Raghupathey Sri Rama Chandra Raghava | G109: 2 Pancham / D | H109: {=IFNA(INDEX(Pitches[],MATCH($G109,Pitches[Pitches],0),2),"")} -> A | I109: {=IF( AND(D109="", E109=""), "", IFNA( IF( INDEX(Singers[], MATCH(IF(D109<>"", B109, C109), Singers[Singers], 0), 2, 0) = "Gents", INDEX(Bhajans[], MATCH(IF(D109<>"", D109, E109), Bhajans[title], 0), 13), INDEX(Bhajans[], MATCH(IF(D109<>"", D109, E109), Bhajans[title], 0), 14) ), "" ) )} -> 2.5 Pancham / D# | J109: {=IF(AND($D109="", $E109=""), "", IFNA(INDEX(Bhajans[], MATCH(IF($D109<>"", $D109, $E109), Bhajans[title], 0), 9), ""))} -> Maand | K109: {=IF(AND($D109="", $E109=""), "", IFNA(INDEX(Bhajans[], MATCH(IF($D109<>"", $D109, $E109), Bhajans[title], 0), 5), ""))} -> Raghupathey Sri Rama Chandra Raghava Daya Nidhey (2) Pashupathey Sri Parvatheesha Shankara Sadashiva (2) Madhava Sri Radhikesha Govinda Harey Krishna (2) | L109: {=IF(AND($D109="", $E109=""), "", IFNA(INDEX(Bhajans[], MATCH(IF($D109<>"", $D109, $E109), Bhajans[title], 0), 4), ""))} -> O Rama, Lord of the Raghus, who is still and shining as the moon, You are the Ocean of Mercy. O Lord Shiva, the beloved of Mother Parvathi, You are ever unchanging and the Source of Goodness. Oh Krishna, the Splendorous Lord of Radha, You are the protector of our souls and the remover of sorrows. Oh Lord Sai, You are Lord Rama, Lord Shiva and Lord Krishna.
A110: 45804 | B110: Shravya | C110: {=IFNA(XLOOKUP(E110,GP_Bhajan_List[GP Bhajan List], GP_Bhajan_List[Singer]),"")} | D110: Danava Bhanjana Rama Sai Shyamala | G110: 2 Pancham / D | H110: {=IFNA(INDEX(Pitches[],MATCH($G110,Pitches[Pitches],0),2),"")} -> A | I110: {=IF( AND(D110="", E110=""), "", IFNA( IF( INDEX(Singers[], MATCH(IF(D110<>"", B110, C110), Singers[Singers], 0), 2, 0) = "Gents", INDEX(Bhajans[], MATCH(IF(D110<>"", D110, E110), Bhajans[title], 0), 13), INDEX(Bhajans[], MATCH(IF(D110<>"", D110, E110), Bhajans[title], 0), 14) ), "" ) )} -> 1 Pancham / C | J110: {=IF(AND($D110="", $E110=""), "", IFNA(INDEX(Bhajans[], MATCH(IF($D110<>"", $D110, $E110), Bhajans[title], 0), 9), ""))} -> Pilu | K110: {=IF(AND($D110="", $E110=""), "", IFNA(INDEX(Bhajans[], MATCH(IF($D110<>"", $D110, $E110), Bhajans[title], 0), 5), ""))} -> Danava Bhanjana Rama Sai Shyamala Komala Ram Hey Rama Rama Jaya Rama Sai Rama Rama Ram [ Danava Bhanjana ... ] Dasharatha Nandana Rama Sai Daya Sagara Ram Deenon Ke Prabhu Rama Sai Rama Rama Ram | L110: {=IF(AND($D110="", $E110=""), "", IFNA(INDEX(Bhajans[], MATCH(IF($D110<>"", $D110, $E110), Bhajans[title], 0), 4), ""))} -> O charming and sweet Lord Rama, You annihilated the demons (Danavas). Victory to You, Lord Rama, son of Dasharatha. You are an ocean of compassion, the refuge to the destitute. O Rama, You are verily our Lord Sai Rama.
A111: 45804 | B111: Ashwin | C111: {=IFNA(XLOOKUP(E111,GP_Bhajan_List[GP Bhajan List], GP_Bhajan_List[Singer]),"")} | H111: {=IFNA(INDEX(Pitches[],MATCH($G111,Pitches[Pitches],0),2),"")} | I111: {=IF( AND(D111="", E111=""), "", IFNA( IF( INDEX(Singers[], MATCH(IF(D111<>"", B111, C111), Singers[Singers], 0), 2, 0) = "Gents", INDEX(Bhajans[], MATCH(IF(D111<>"", D111, E111), Bhajans[title], 0), 13), INDEX(Bhajans[], MATCH(IF(D111<>"", D111, E111), Bhajans[title], 0), 14) ), "" ) )} | J111: {=IF(AND($D111="", $E111=""), "", IFNA(INDEX(Bhajans[], MATCH(IF($D111<>"", $D111, $E111), Bhajans[title], 0), 9), ""))} | K111: {=IF(AND($D111="", $E111=""), "", IFNA(INDEX(Bhajans[], MATCH(IF($D111<>"", $D111, $E111), Bhajans[title], 0), 5), ""))} | L111: {=IF(AND($D111="", $E111=""), "", IFNA(INDEX(Bhajans[], MATCH(IF($D111<>"", $D111, $E111), Bhajans[title], 0), 4), ""))}
A112: 45805 | B112: Jothsna | C112: {=IFNA(XLOOKUP(E112,GP_Bhajan_List[GP Bhajan List], GP_Bhajan_List[Singer]),"")} | D112: Vighna Vinashaka Gananatha | G112: 5 Pancham / G | H112: {=IFNA(INDEX(Pitches[],MATCH($G112,Pitches[Pitches],0),2),"")} -> D | I112: {=IF( AND(D112="", E112=""), "", IFNA( IF( INDEX(Singers[], MATCH(IF(D112<>"", B112, C112), Singers[Singers], 0), 2, 0) = "Gents", INDEX(Bhajans[], MATCH(IF(D112<>"", D112, E112), Bhajans[title], 0), 13), INDEX(Bhajans[], MATCH(IF(D112<>"", D112, E112), Bhajans[title], 0), 14) ), "" ) )} -> 5.5 Pancham / G# | J112: {=IF(AND($D112="", $E112=""), "", IFNA(INDEX(Bhajans[], MATCH(IF($D112<>"", $D112, $E112), Bhajans[title], 0), 9), ""))} -> Janasammohini | K112: {=IF(AND($D112="", $E112=""), "", IFNA(INDEX(Bhajans[], MATCH(IF($D112<>"", $D112, $E112), Bhajans[title], 0), 5), ""))} -> Vighna Vinashaka Gananatha Gajanana Hey Gajavadana Gananatha Gananatha Pranava Swaroopa Gananatha Parthi Pureeshwara Gananatha [ Gajanana Hey ... ] | L112: {=IF(AND($D112="", $E112=""), "", IFNA(INDEX(Bhajans[], MATCH(IF($D112<>"", $D112, $E112), Bhajans[title], 0), 4), ""))} -> The elephant faced Lord Ganesha is the leader of ganaas (the attendants of Lord Shiva) and the destroyer of all obstacles. He is the embodiment of primordial sound "Om". He is verily Lord Sai who resides in Parthi.
A113: 45805 | B113: Prithvi | C113: {=IFNA(XLOOKUP(E113,GP_Bhajan_List[GP Bhajan List], GP_Bhajan_List[Singer]),"")} | D113: Buddha Mahavir Yesu Sai | G113: 1.5 Pancham / C# | H113: {=IFNA(INDEX(Pitches[],MATCH($G113,Pitches[Pitches],0),2),"")} -> G# | I113: {=IF( AND(D113="", E113=""), "", IFNA( IF( INDEX(Singers[], MATCH(IF(D113<>"", B113, C113), Singers[Singers], 0), 2, 0) = "Gents", INDEX(Bhajans[], MATCH(IF(D113<>"", D113, E113), Bhajans[title], 0), 13), INDEX(Bhajans[], MATCH(IF(D113<>"", D113, E113), Bhajans[title], 0), 14) ), "" ) )} -> 6.5 Pancham / A# | J113: {=IF(AND($D113="", $E113=""), "", IFNA(INDEX(Bhajans[], MATCH(IF($D113<>"", $D113, $E113), Bhajans[title], 0), 9), ""))} -> Shankarabharanam / Bilawal | K113: {=IF(AND($D113="", $E113=""), "", IFNA(INDEX(Bhajans[], MATCH(IF($D113<>"", $D113, $E113), Bhajans[title], 0), 5), ""))} -> Buddha Mahavir Yesu Sai Vahey Guru Vahey Guru Bol Manuva Allah Yesu Sadguru Sai Geeta Veda Quran Ho Sai Tan Mey Sai Man Mey Sai Rom Rom Mey Sai Sai [ Vahey Guru ... ] | L113: {=IF(AND($D113="", $E113=""), "", IFNA(INDEX(Bhajans[], MATCH(IF($D113<>"", $D113, $E113), Bhajans[title], 0), 4), ""))} -> O mind, chant the name of Vahey Guru, Buddha, Mahavir, Jesus and the Divine Preceptor Sai, who are the essence of scriptures Bagawad Gita, Quran and Bible. O Sai, You are the indweller of the body and mind and every atom of body is filled by You.
...

Sheet Instrumentalist Roster
A1: Date | B1: Harmonium | C1: Chorus Mic | D1: Tabla | E1: Cymbals (Male) | F1: Cymbals (Female) | G1: Tambourine | H1: Ghanjira (small)
A2: 45734
A3: 45735
A4: 45736
A5: 45737
A6: 45738
A7: 45739
A8: 45748
A9: 45749
A10: 45750
A11: 45751
A12: 45752
A13: 45753
... A33: 45758
A34: 45776 | B34: Gowtem | D34: Gowtem | E34: Gowtem | F34: Gowtem | G34: Gowtem | H34: Gowtem
A35: 45777 | B35: Prithvi | D35: Prithvi | E35: Prithvi | F35: Prithvi | G35: Prithvi | H35: Prithvi
A36: 45778 | B36: Gowtem | D36: Sailavan | E36: Sriram | F36: Triveni | G36: Rhuben | H36: Prahalad
A37: 45779 | B37: Gowtem | D37: Rhuben | E37: Sriram | F37: Triveni | G37: Rhuben | H37: Prahalad
A38: 45781 | B38: Prithvi | D38: Sailavan | E38: Sriram | F38: Triveni | G38: Rhuben | H38: Prahalad
A39: 45783 | B39: Prithvi | D39: Rhuben | E39: Sriram | F39: Triveni | G39: Sriraag | H39: Prahalad
A40: 45784 | B40: Gowtem | D40: Sailavan | E40: Sriram | F40: Triveni | G40: Rhuben | H40: Prahalad
A41: 45785 | B41: Prithvi | D41: Rhuben, Sriraag | E41: Sriram | F41: Triveni | G41: Sailavan | H41: Prahalad
A42: 45786 | B42: Gowtem | D42: Rhuben | E42: Sriram | F42: Triveni | G42: Rhuben | H42: Prahalad
A43: 45787 | B43: Prithvi | D43: Rhuben | E43: Sriram | F43: Triveni | G43: Rhuben | H43: Prahalad
A44: 45788 | B44: Gowtem | D44: Sriraag | E44: Sriram | F44: Sriram | G44: Rhuben | H44: Prahalad
A45: 45790 | B45: Prithvi | D45: Sriraag | E45: Sriram | F45: Triveni | G45: Rhuben | H45: Prahalad
A46: 45791 | B46: Prithvi | D46: Sailavan | E46: Sriram | F46: Triveni | G46: Rhuben | H46: Prahalad
A47: 45792 | B47: Prithvi | D47: Rhuben | E47: Sriram | F47: Triveni | H47: Prahalad
A48: 45802
A49: 45804
A50: 45805
A51: 45806
A52: 45807
A53: 45808 | B53: Gowtem | D53: Sriraag | E53: Sriram | F53: Triveni | G53: Rhuben | H53: Prahalad
A54: 45809
A55: 45811
A56: 45812
A57: 45813
A58: 45814
A59: 45815 | B59: Gowtem | D59: Sriraag | E59: Sriram | F59: Triveni | G59: Rhuben | H59: Prahalad
...

Sheet Sheet38
A1: Ashwin | B1: =COUNTIF('Singer Roster'!$B$791:'Singer Roster'!$B$1100,A1) -> 25 | D1: Ashwin | E1: =COUNTIFS(Singing_Roster[Singer],D1,Singing_Roster[Bhajan],"<>") -> 98
A2: Sailavan | B2: =COUNTIF('Singer Roster'!$B$791:'Singer Roster'!$B$1100,A2) -> 26 | D2: Sailavan | E2: =COUNTIFS(Singing_Roster[Singer],D2,Singing_Roster[Bhajan],"<>") -> 104
A3: Prithvi | B3: =COUNTIF('Singer Roster'!$B$791:'Singer Roster'!$B$1100,A3) -> 28 | D3: Prithvi | E3: =COUNTIFS(Singing_Roster[Singer],D3,Singing_Roster[Bhajan],"<>") -> 91
A4: Jothsna | B4: =COUNTIF('Singer Roster'!$B$791:'Singer Roster'!$B$1100,A4) -> 24 | D4: Jothsna | E4: =COUNTIFS(Singing_Roster[Singer],D4,Singing_Roster[Bhajan],"<>") -> 72
A5: Shravya | B5: =COUNTIF('Singer Roster'!$B$791:'Singer Roster'!$B$1100,A5) -> 10 | D5: Shravya | E5: =COUNTIFS(Singing_Roster[Singer],D5,Singing_Roster[Bhajan],"<>") -> 40
D6: Sriraag | E6: =COUNTIFS(Singing_Roster[Singer],D6,Singing_Roster[Bhajan],"<>") -> 40
D7: Rhuben | E7: =COUNTIFS(Singing_Roster[Singer],D7,Singing_Roster[Bhajan],"<>") -> 36
D8: Pavitra | E8: =COUNTIFS(Singing_Roster[Singer],D8,Singing_Roster[Bhajan],"<>") -> 42
D9: Prasanna | E9: =COUNTIFS(Singing_Roster[Singer],D9,Singing_Roster[Bhajan],"<>") -> 65
D10: Anvita | E10: =COUNTIFS(Singing_Roster[Singer],D10,Singing_Roster[Bhajan],"<>") -> 27
